GTCEuStartupEvents.registry('gtceu:recipe_type', event => {
    event.create('eye_homo')
        .setEUIO('in')
        .setMaxIOSize(2, 27, 1, 3)
        .setSlotOverlay(false, false, GuiTextures.SOLIDIFIER_OVERLAY)
        .setProgressBar(GuiTextures.PROGRESS_BAR_ARROW, FillDirection.LEFT_TO_RIGHT)
        .setSound(GTSoundEntries.CHEMICAL)
})
GTCEuStartupEvents.registry('gtceu:machine', event => {
    event.create('eye_homo', 'multiblock')
        .rotationState(RotationState.ALL)
        .recipeType('eye_homo')
        .appearanceBlock(() => Block.getBlock('gtceu:steam_machine_casing'))
        .pattern(definition => FactoryBlockPattern.start()
            .aisle("                                 ", "                                 ", "                                 ", "                                 ", "                                 ", "                                 ", "                                 ", "                                 ", "                                 ", "                                 ", "                                 ", "                                 ", "               A A               ", "               A A               ", "               A A               ", "            AAAAAAAAA            ", "               A A               ", "            AAAAAAAAA            ", "               A A               ", "               A A               ", "               A A               ", "                                 ", "                                 ", "                                 ", "                                 ", "                                 ", "                                 ", "                                 ", "                                 ", "                                 ", "                                 ", "                                 ", "                                 ")
            .aisle("                                 ", "                                 ", "                                 ", "                                 ", "                                 ", "                                 ", "                                 ", "                                 ", "                                 ", "               A A               ", "               A A               ", "               A A               ", "               A A               ", "              DDDDD              ", "             DDADADD             ", "         AAAADAADAADAAAA         ", "             DDDDDDD             ", "         AAAADAADAADAAAA         ", "             DDADADD             ", "              DDDDD              ", "               A A               ", "               A A               ", "               A A               ", "               A A               ", "                                 ", "                                 ", "                                 ", "                                 ", "                                 ", "                                 ", "                                 ", "                                 ", "                                 ")
            .aisle("                                 ", "                                 ", "                                 ", "                                 ", "                                 ", "                                 ", "                                 ", "               A A               ", "               A A               ", "               A A               ", "                D                ", "                D                ", "             DDDDDDD             ", "            DD     DD            ", "            D  EEE  D            ", "       AAA  D EFFFE D  AAA       ", "          DDD EFFFE DDD          ", "       AAA  D EFFFE D  AAA       ", "            D  EEE  D            ", "            DD     DD            ", "             DDDDDDD             ", "                D                ", "                D                ", "               A A               ", "               A A               ", "               A A               ", "                                 ", "                                 ", "                                 ", "                                 ", "                                 ", "                                 ", "                                 ")
            .aisle("                                 ", "                                 ", "                                 ", "                                 ", "                                 ", "                                 ", "               A A               ", "               A A               ", "                D                ", "                D                ", "                                 ", "                                 ", "                                 ", "                                 ", "                                 ", "      AA                 AA      ", "        DD             DD        ", "      AA                 AA      ", "                                 ", "                                 ", "                                 ", "                                 ", "                                 ", "                D                ", "                D                ", "               A A               ", "               A A               ", "                                 ", "                                 ", "                                 ", "                                 ", "                                 ", "                                 ")
            .aisle("                                 ", "                                 ", "                                 ", "                                 ", "                                 ", "               A A               ", "              AAAAA              ", "                D                ", "                F                ", "                F                ", "                                 ", "                                 ", "                                 ", "                                 ", "      A                   A      ", "     AA                   AA     ", "      ADFF             FFDA      ", "     AA                   AA     ", "      A                   A      ", "                                 ", "                                 ", "                                 ", "                                 ", "                F                ", "                F                ", "                D                ", "              AAAAA              ", "               A A               ", "                                 ", "                                 ", "                                 ", "                                 ", "                                 ")
            .aisle("                                 ", "                                 ", "                                 ", "                                 ", "               A A               ", "               A A               ", "                D                ", "             GEEFEEG             ", "                                 ", "                                 ", "                                 ", "                                 ", "                                 ", "       G                 G       ", "       E                 E       ", "    AA E                 E AA    ", "      DF                 FD      ", "    AA E                 E AA    ", "       E                 E       ", "       G                 G       ", "                                 ", "                                 ", "                                 ", "                                 ", "                                 ", "             GEEFEEG             ", "                D                ", "               A A               ", "               A A               ", "                                 ", "                                 ", "                                 ", "                                 ")
            .aisle("                                 ", "                                 ", "                                 ", "               A A               ", "              AAAAA              ", "                D                ", "                F                ", "                                 ", "                                 ", "                                 ", "                                 ", "                                 ", "                                 ", "                                 ", "    A                       A    ", "   AA                       AA   ", "    ADF                   FDA    ", "   AA                       AA   ", "    A                       A    ", "                                 ", "                                 ", "                                 ", "                                 ", "                                 ", "                                 ", "                                 ", "                F                ", "                D                ", "              AAAAA              ", "               A A               ", "                                 ", "                                 ", "                                 ")
            .aisle("                                 ", "                                 ", "               A A               ", "               A A               ", "                D                ", "             GEEFEEG             ", "                                 ", "                                 ", "                                 ", "                                 ", "                                 ", "                                 ", "                                 ", "     G                     G     ", "     E                     E     ", "  AA E                     E AA  ", "    DF                     FD    ", "  AA E                     E AA  ", "     E                     E     ", "     G                     G     ", "                                 ", "                                 ", "                                 ", "                                 ", "                                 ", "                                 ", "                                 ", "             GEEFEEG             ", "                D                ", "               A A               ", "               A A               ", "                                 ", "                                 ")
            .aisle("                                 ", "                                 ", "               A A               ", "                D                ", "                F                ", "                                 ", "                                 ", "                                 ", "                                 ", "                                 ", "                                 ", "                                 ", "                                 ", "                                 ", "                                 ", "  A                           A  ", "   DF                       FD   ", "  A                           A  ", "                                 ", "                                 ", "                                 ", "                                 ", "                                 ", "                                 ", "                                 ", "                                 ", "                                 ", "                                 ", "                F                ", "                D                ", "               A A               ", "                                 ", "                                 ")
            .aisle("                                 ", "               A A               ", "               A A               ", "                D                ", "                F                ", "                                 ", "                                 ", "                                 ", "                                 ", "                                 ", "                                 ", "                                 ", "                                 ", "                                 ", "                                 ", " AA                           AA ", "   DF                       FD   ", " AA                           AA ", "                                 ", "                                 ", "                                 ", "                                 ", "                                 ", "                                 ", "                                 ", "                                 ", "                                 ", "                                 ", "                F                ", "                D                ", "               A A               ", "               A A               ", "                                 ")
            .aisle("                                 ", "               A A               ", "                D                ", "                                 ", "                                 ", "                                 ", "                                 ", "                                 ", "                                 ", "                                 ", "                                 ", "                                 ", "                                 ", "                                 ", "                                 ", " A                             A ", "  D                           D  ", " A                             A ", "                                 ", "                                 ", "                                 ", "                                 ", "                                 ", "                                 ", "                                 ", "                                 ", "                                 ", "                                 ", "                                 ", "                                 ", "                D                ", "               A A               ", "                                 ")
            .aisle("                                 ", "               A A               ", "                D                ", "                                 ", "                                 ", "                                 ", "                                 ", "                                 ", "                                 ", "                                 ", "                                 ", "                                 ", "                                 ", "                                 ", "                                 ", " A                             A ", "  D                           D  ", " A                             A ", "                                 ", "                                 ", "                                 ", "                                 ", "                                 ", "                                 ", "                                 ", "                                 ", "                                 ", "                                 ", "                                 ", "                                 ", "                D                ", "               A A               ", "                                 ")
            .aisle("               A A               ", "               A A               ", "             DDDDDDD             ", "                                 ", "                                 ", "                                 ", "                                 ", "                                 ", "                                 ", "                                 ", "                                 ", "                                 ", "                                 ", "  D                           D  ", "  D                           D  ", "AAD                           DAA", "  D                           D  ", "AAD                           DAA", "  D                           D  ", "  D                           D  ", "                                 ", "                                 ", "                                 ", "                                 ", "                                 ", "                                 ", "                                 ", "                                 ", "                                 ", "                                 ", "             DDDDDDD             ", "               A A               ", "               A A               ")
            .aisle("               A A               ", "              DDDDD              ", "            DD     DD            ", "                                 ", "                                 ", "       G                 G       ", "                                 ", "     G                     G     ", "                                 ", "                                 ", "                                 ", "                                 ", "  D                           D  ", "  D                           D  ", " D                             D ", "AD                             DA", " D                             D ", "AD                             DA", " D                             D ", "  D                           D  ", "  D                           D  ", "                                 ", "                                 ", "                                 ", "                                 ", "     G                     G     ", "                                 ", "       G                 G       ", "                                 ", "                                 ", "            DD     DD            ", "              DDDDD              ", "               A A               ")
            .aisle("               A A               ", "             DDADADD             ", "            D  EEE  D            ", "                                 ", "      A                   A      ", "       E                 E       ", "    A                       A    ", "     E                     E     ", "                                 ", "                                 ", "                                 ", "                                 ", "  D                           D  ", " D                             D ", " D                             D ", "AAE                           EAA", " DE                           ED ", "AAE                           EAA", " D                             D ", " D                             D ", "  D                           D  ", "                                 ", "                                 ", "                                 ", "                                 ", "     E                     E     ", "    A                       A    ", "       E                 E       ", "      A                   A      ", "                                 ", "            D  EEE  D            ", "             DDADADD             ", "               A A               ")
            .aisle("            AAAAAAAAA            ", "         AAAADAADAADAAAA         ", "       AAA  D EFFFE D  AAA       ", "      AA                 AA      ", "     AA                   AA     ", "    AA E                 E AA    ", "   AA                       AA   ", "  AA E                     E AA  ", "  A                           A  ", " AA                           AA ", " A                             A ", " A                             A ", "AAD                           DAA", "AD                             DA", "AAE                           EAA", "AAF                           FAA", "ADF                           FDA", "AAF                           FAA", "AAE                           EAA", "AD                             DA", "AAD                           DAA", " A                             A ", " A                             A ", " AA                           AA ", "  A                           A  ", "  AA E                     E AA  ", "   AA                       AA   ", "    AA E                 E AA    ", "     AA                   AA     ", "      AA                 AA      ", "       AAA  D EFFFE D  AAA       ", "         AAAADAADAADAAAA         ", "            AAAAAAAAA            ")
            .aisle("               A A               ", "             DDDDDDD             ", "          DDD EFFFE DDD          ", "        DD             DD        ", "      ADFF             FFDA      ", "      DF                 FD      ", "    ADF                   FDA    ", "    DF                     FD    ", "   DF                       FD   ", "   DF                       FD   ", "  D                           D  ", "  D                           D  ", "  D                           D  ", " D                             D ", " DE                           ED ", "ADF                           FDA", " DF                           FD ", "ADF                           FDA", " DE                           ED ", " D                             D ", "  D                           D  ", "  D                           D  ", "  D                           D  ", "   DF                       FD   ", "   DF                       FD   ", "    DF                     FD    ", "    ADF                   FDA    ", "      DF                 FD      ", "      ADFF             FFDA      ", "        DD             DD        ", "          DDD EFFFE DDD          ", "             DDDDDDD             ", "               A A               ")
            .aisle("            AAAAAAAAA            ", "         AAAADAADAADAAAA         ", "       AAA  D EFFFE D  AAA       ", "      AA                 AA      ", "     AA                   AA     ", "    AA E                 E AA    ", "   AA                       AA   ", "  AA E                     E AA  ", "  A                           A  ", " AA                           AA ", " A                             A ", " A                             A ", "AAD                           DAA", "AD                             DA", "AAE                           EAA", "AAF                           FAA", "ADF                           FDA", "AAF                           FAA", "AAE                           EAA", "AD                             DA", "AAD                           DAA", " A                             A ", " A                             A ", " AA                           AA ", "  A                           A  ", "  AA E                     E AA  ", "   AA                       AA   ", "    AA E                 E AA    ", "     AA                   AA     ", "      AA                 AA      ", "       AAA  D EFFFE D  AAA       ", "         AAAADAADAADAAAA         ", "            AAAAAAAAA            ")
            .aisle("               A A               ", "             DDADADD             ", "            D  EEE  D            ", "                                 ", "      A                   A      ", "       E                 E       ", "    A                       A    ", "     E                     E     ", "                                 ", "                                 ", "                                 ", "                                 ", "  D                           D  ", " D                             D ", " D                             D ", "AAE                           EAA", " DE                           ED ", "AAE                           EAA", " D                             D ", " D                             D ", "  D                           D  ", "                                 ", "                                 ", "                                 ", "                                 ", "     E                     E     ", "    A                       A    ", "       E                 E       ", "      A                   A      ", "                                 ", "            D  EEE  D            ", "             DDADADD             ", "               A A               ")
            .aisle("               A A               ", "              DDDDD              ", "            DD     DD            ", "                                 ", "                                 ", "       G                 G       ", "                                 ", "     G                     G     ", "                                 ", "                                 ", "                                 ", "                                 ", "  D                           D  ", "  D                           D  ", " D                             D ", "AD                             DA", " D                             D ", "AD                             DA", " D                             D ", "  D                           D  ", "  D                           D  ", "                                 ", "                                 ", "                                 ", "                                 ", "     G                     G     ", "                                 ", "       G                 G       ", "                                 ", "                                 ", "            DD     DD            ", "              DDDDD              ", "               A A               ")
            .aisle("               A A               ", "               A A               ", "             DDDDDDD             ", "                                 ", "                                 ", "                                 ", "                                 ", "                                 ", "                                 ", "                                 ", "                                 ", "                                 ", "                                 ", "  D                           D  ", "  D                           D  ", "AAD                           DAA", "  D                           D  ", "AAD                           DAA", "  D                           D  ", "  D                           D  ", "                                 ", "                                 ", "                                 ", "                                 ", "                                 ", "                                 ", "                                 ", "                                 ", "                                 ", "                                 ", "             DDDDDDD             ", "               A A               ", "               A A               ")
            .aisle("                                 ", "               A A               ", "                D                ", "                                 ", "                                 ", "                                 ", "                                 ", "                                 ", "                                 ", "                                 ", "                                 ", "                                 ", "                                 ", "                                 ", "                                 ", " A                             A ", "  D                           D  ", " A                             A ", "                                 ", "                                 ", "                                 ", "                                 ", "                                 ", "                                 ", "                                 ", "                                 ", "                                 ", "                                 ", "                                 ", "                                 ", "                D                ", "               A A               ", "                                 ")
            .aisle("                                 ", "               A A               ", "                D                ", "                                 ", "                                 ", "                                 ", "                                 ", "                                 ", "                                 ", "                                 ", "                                 ", "                                 ", "                                 ", "                                 ", "                                 ", " A                             A ", "  D                           D  ", " A                             A ", "                                 ", "                                 ", "                                 ", "                                 ", "                                 ", "                                 ", "                                 ", "                                 ", "                                 ", "                                 ", "                                 ", "                                 ", "                D                ", "               A A               ", "                                 ")
            .aisle("                                 ", "               A A               ", "               A A               ", "                D                ", "                F                ", "                                 ", "                                 ", "                                 ", "                                 ", "                                 ", "                                 ", "                                 ", "                                 ", "                                 ", "                                 ", " AA                           AA ", "   DF                       FD   ", " AA                           AA ", "                                 ", "                                 ", "                                 ", "                                 ", "                                 ", "                                 ", "                                 ", "                                 ", "                                 ", "                                 ", "                F                ", "                D                ", "               A A               ", "               A A               ", "                                 ")
            .aisle("                                 ", "                                 ", "               A A               ", "                D                ", "                F                ", "                                 ", "                                 ", "                                 ", "                                 ", "                                 ", "                                 ", "                                 ", "                                 ", "                                 ", "                                 ", "  A                           A  ", "   DF                       FD   ", "  A                           A  ", "                                 ", "                                 ", "                                 ", "                                 ", "                                 ", "                                 ", "                                 ", "                                 ", "                                 ", "                                 ", "                F                ", "                D                ", "               A A               ", "                                 ", "                                 ")
            .aisle("                                 ", "                                 ", "               A A               ", "               A A               ", "                D                ", "             GEEFEEG             ", "                                 ", "                                 ", "                                 ", "                                 ", "                                 ", "                                 ", "                                 ", "     G                     G     ", "     E                     E     ", "  AA E                     E AA  ", "    DF                     FD    ", "  AA E                     E AA  ", "     E                     E     ", "     G                     G     ", "                                 ", "                                 ", "                                 ", "                                 ", "                                 ", "                                 ", "                                 ", "             GEEFEEG             ", "                D                ", "               A A               ", "               A A               ", "                                 ", "                                 ")
            .aisle("                                 ", "                                 ", "                                 ", "               A A               ", "              AAAAA              ", "                D                ", "                F                ", "                                 ", "                                 ", "                                 ", "                                 ", "                                 ", "                                 ", "                                 ", "    A                       A    ", "   AA                       AA   ", "    ADF                   FDA    ", "   AA                       AA   ", "    A                       A    ", "                                 ", "                                 ", "                                 ", "                                 ", "                                 ", "                                 ", "                                 ", "                F                ", "                D                ", "              AAAAA              ", "               A A               ", "                                 ", "                                 ", "                                 ")
            .aisle("                                 ", "                                 ", "                                 ", "                                 ", "               A A               ", "               A A               ", "                D                ", "             GEEFEEG             ", "                                 ", "                                 ", "                                 ", "                                 ", "                                 ", "       G                 G       ", "       E                 E       ", "    AA E                 E AA    ", "      DF                 FD      ", "    AA E                 E AA    ", "       E                 E       ", "       G                 G       ", "                                 ", "                                 ", "                                 ", "                                 ", "                                 ", "             GEEFEEG             ", "                D                ", "               A A               ", "               A A               ", "                                 ", "                                 ", "                                 ", "                                 ")
            .aisle("                                 ", "                                 ", "                                 ", "                                 ", "                                 ", "               A A               ", "              AAAAA              ", "                D                ", "                F                ", "                F                ", "                                 ", "                                 ", "                                 ", "                                 ", "      A                   A      ", "     AA                   AA     ", "      ADFF             FFDA      ", "     AA                   AA     ", "      A                   A      ", "                                 ", "                                 ", "                                 ", "                                 ", "                F                ", "                F                ", "                D                ", "              AAAAA              ", "               A A               ", "                                 ", "                                 ", "                                 ", "                                 ", "                                 ")
            .aisle("                                 ", "                                 ", "                                 ", "                                 ", "                                 ", "                                 ", "               A A               ", "               A A               ", "                D                ", "                D                ", "                                 ", "                                 ", "                                 ", "                                 ", "                                 ", "      AA                 AA      ", "        DD             DD        ", "      AA                 AA      ", "                                 ", "                                 ", "                                 ", "                                 ", "                                 ", "                D                ", "                D                ", "               A A               ", "               A A               ", "                                 ", "                                 ", "                                 ", "                                 ", "                                 ", "                                 ")
            .aisle("                                 ", "                                 ", "                                 ", "                                 ", "                                 ", "                                 ", "                                 ", "               A A               ", "               A A               ", "               A A               ", "                D                ", "                D                ", "             DDDDDDD             ", "            DD     DD            ", "            D  EEE  D            ", "       AAA  D EFFFE D  AAA       ", "          DDD EFFFE DDD          ", "       AAA  D EFFFE D  AAA       ", "            D  EEE  D            ", "            DD     DD            ", "             DDDDDDD             ", "                D                ", "                D                ", "               A A               ", "               A A               ", "               A A               ", "                                 ", "                                 ", "                                 ", "                                 ", "                                 ", "                                 ", "                                 ")
            .aisle("                                 ", "                                 ", "                                 ", "                                 ", "                                 ", "                                 ", "                                 ", "                                 ", "                                 ", "               A A               ", "               A A               ", "               A A               ", "               A A               ", "              DDDDD              ", "             DDADADD             ", "         AAAADAADAADAAAA         ", "             DDDDDDD             ", "         AAAADAADAADAAAA         ", "             DDADADD             ", "              DDDDD              ", "               A A               ", "               A A               ", "               A A               ", "               A A               ", "                                 ", "                                 ", "                                 ", "                                 ", "                                 ", "                                 ", "                                 ", "                                 ", "                                 ")
            .aisle("                                 ", "                                 ", "                                 ", "                                 ", "                                 ", "                                 ", "                                 ", "                                 ", "                                 ", "                                 ", "                                 ", "                                 ", "             AAAAAAA             ", "            AABBBBBAA            ", "            ABBBBBBBA            ", "            ABBAAABBA            ", "            ABBA~ABBA            ", "            ABBAAABBA            ", "            ABBBBBBBA            ", "            AABBBBBAA            ", "             AAAAAAA             ", "                                 ", "                                 ", "                                 ", "                                 ", "                                 ", "                                 ", "                                 ", "                                 ", "                                 ", "                                 ", "                                 ", "                                 ")
            .where('~', Predicates.controller(Predicates.blocks(definition.get())))
            .where('A', Predicates.blocks('minecraft:bricks'))
            .where('B', Predicates.blocks('gtceu:steam_machine_casing')
                .or(Predicates.abilities(PartAbility.STEAM))
                .or(Predicates.abilities(PartAbility.EXPORT_ITEMS))
                .or(Predicates.abilities(PartAbility.STEAM_EXPORT_ITEMS).setPreviewCount(9))
                .or(Predicates.autoAbilities(definition.getRecipeTypes())))
            .where('D', Predicates.blocks('minecraft:oak_planks'))
            .where('E', Predicates.blocks('minecraft:lapis_block'))
            .where('F', Predicates.blocks('minecraft:bookshelf'))
            .where('G', Predicates.blocks('minecraft:chiseled_stone_bricks'))
            .where(" ", Predicates.any())
            .build())
        .workableCasingRenderer("gtceu:block/casings/solid/machine_casing_bronze_plated_bricks", 'gtceu:block/multiblock/fusion_reactor')
})

//我爱tst