GTCEuStartupEvents.registry('gtceu:recipe_type', event => {
    event.create('eye_homo')
        .setEUIO('in')
        .setMaxIOSize(2, 27, 1, 3)
        .setSlotOverlay(false, false, GuiTextures.SOLIDIFIER_OVERLAY)
        .setProgressBar(GuiTextures.PROGRESS_BAR_ARROW, FillDirection.LEFT_TO_RIGHT)
        .setSound(GTSoundEntries.CHEMICAL)
})
GTCEuStartupEvents.registry('gtceu:machine', event => {
    event.create('eye_homo', 'multiblock')
        .rotationState(RotationState.ALL)
        .recipeType('eye_homo')
        .appearanceBlock(() => Block.getBlock('gtceu:steam_machine_casing'))
        .pattern(definition => FactoryBlockPattern.start()
            .aisle("#################################", "#################################", "#################################", "#################################", "#################################", "#################################", "#################################", "#################################", "#################################", "#################################", "#################################", "#################################", "###############A#A###############", "###############A#A###############", "###############A#A###############", "############AAAAAAAAA############", "###############A#A###############", "############AAAAAAAAA############", "###############A#A###############", "###############A#A###############", "###############A#A###############", "#################################", "#################################", "#################################", "#################################", "#################################", "#################################", "#################################", "#################################", "#################################", "#################################", "#################################", "#################################")
            .aisle("#################################", "#################################", "#################################", "#################################", "#################################", "#################################", "#################################", "#################################", "#################################", "###############A#A###############", "###############A#A###############", "###############A#A###############", "###############A#A###############", "##############BBBBB##############", "#############BBABABB#############", "#########AAAABAABAABAAAA#########", "#############BBBBBBB#############", "#########AAAABAABAABAAAA#########", "#############BBABABB#############", "##############BBBBB##############", "###############A#A###############", "###############A#A###############", "###############A#A###############", "###############A#A###############", "#################################", "#################################", "#################################", "#################################", "#################################", "#################################", "#################################", "#################################", "#################################")
            .aisle("#################################", "#################################", "#################################", "#################################", "#################################", "#################################", "#################################", "###############A#A###############", "###############A#A###############", "###############A#A###############", "################B################", "################B################", "#############BBBBBBB#############", "############BB#####BB############", "############B##CCC##B############", "#######AAA##B#CDDDC#B##AAA#######", "##########BBB#CDDDC#BBB##########", "#######AAA##B#CDDDC#B##AAA#######", "############B##CCC##B############", "############BB#####BB############", "#############BBBBBBB#############", "################B################", "################B################", "###############A#A###############", "###############A#A###############", "###############A#A###############", "#################################", "#################################", "#################################", "#################################", "#################################", "#################################", "#################################")
            .aisle("#################################", "#################################", "#################################", "#################################", "#################################", "#################################", "###############A#A###############", "###############A#A###############", "################B################", "################B################", "#################################", "#################################", "#################################", "#################################", "#################################", "######AA#################AA######", "########BB#############BB########", "######AA#################AA######", "#################################", "#################################", "#################################", "#################################", "#################################", "################B################", "################B################", "###############A#A###############", "###############A#A###############", "#################################", "#################################", "#################################", "#################################", "#################################", "#################################")
            .aisle("#################################", "#################################", "#################################", "#################################", "#################################", "###############A#A###############", "##############AAAAA##############", "################B################", "################D################", "################D################", "#################################", "#################################", "#################################", "#################################", "######A###################A######", "#####AA###################AA#####", "######ABDD#############DDBA######", "#####AA###################AA#####", "######A###################A######", "#################################", "#################################", "#################################", "#################################", "################D################", "################D################", "################B################", "##############AAAAA##############", "###############A#A###############", "#################################", "#################################", "#################################", "#################################", "#################################")
            .aisle("#################################", "#################################", "#################################", "#################################", "###############A#A###############", "###############A#A###############", "################B################", "#############ECCDCCE#############", "#################################", "#################################", "#################################", "#################################", "#################################", "#######E#################E#######", "#######C#################C#######", "####AA#C#################C#AA####", "######BD#################DB######", "####AA#C#################C#AA####", "#######C#################C#######", "#######E#################E#######", "#################################", "#################################", "#################################", "#################################", "#################################", "#############ECCDCCE#############", "################B################", "###############A#A###############", "###############A#A###############", "#################################", "#################################", "#################################", "#################################")
            .aisle("#################################", "#################################", "#################################", "###############A#A###############", "##############AAAAA##############", "################B################", "################D################", "#################################", "#################################", "#################################", "#################################", "#################################", "#################################", "#################################", "####A#######################A####", "###AA#######################AA###", "####ABD###################DBA####", "###AA#######################AA###", "####A#######################A####", "#################################", "#################################", "#################################", "#################################", "#################################", "#################################", "#################################", "################D################", "################B################", "##############AAAAA##############", "###############A#A###############", "#################################", "#################################", "#################################")
            .aisle("#################################", "#################################", "###############A#A###############", "###############A#A###############", "################B################", "#############ECCDCCE#############", "#################################", "#################################", "#################################", "#################################", "#################################", "#################################", "#################################", "#####E#####################E#####", "#####C#####################C#####", "##AA#C#####################C#AA##", "####BD#####################DB####", "##AA#C#####################C#AA##", "#####C#####################C#####", "#####E#####################E#####", "#################################", "#################################", "#################################", "#################################", "#################################", "#################################", "#################################", "#############ECCDCCE#############", "################B################", "###############A#A###############", "###############A#A###############", "#################################", "#################################")
            .aisle("#################################", "#################################", "###############A#A###############", "################B################", "################D################", "#################################", "#################################", "#################################", "#################################", "#################################", "#################################", "#################################", "#################################", "#################################", "#################################", "##A###########################A##", "###BD#######################DB###", "##A###########################A##", "#################################", "#################################", "#################################", "#################################", "#################################", "#################################", "#################################", "#################################", "#################################", "#################################", "################D################", "################B################", "###############A#A###############", "#################################", "#################################")
            .aisle("#################################", "###############A#A###############", "###############A#A###############", "################B################", "################D################", "#################################", "#################################", "#################################", "#################################", "#################################", "#################################", "#################################", "#################################", "#################################", "#################################", "#AA###########################AA#", "###BD#######################DB###", "#AA###########################AA#", "#################################", "#################################", "#################################", "#################################", "#################################", "#################################", "#################################", "#################################", "#################################", "#################################", "################D################", "################B################", "###############A#A###############", "###############A#A###############", "#################################")
            .aisle("#################################", "###############A#A###############", "################B################", "#################################", "#################################", "#################################", "#################################", "#################################", "#################################", "#################################", "#################################", "#################################", "#################################", "#################################", "#################################", "#A#############################A#", "##B###########################B##", "#A#############################A#", "#################################", "#################################", "#################################", "#################################", "#################################", "#################################", "#################################", "#################################", "#################################", "#################################", "#################################", "#################################", "################B################", "###############A#A###############", "#################################")
            .aisle("#################################", "###############A#A###############", "################B################", "#################################", "#################################", "#################################", "#################################", "#################################", "#################################", "#################################", "#################################", "#################################", "#################################", "#################################", "#################################", "#A#############################A#", "##B###########################B##", "#A#############################A#", "#################################", "#################################", "#################################", "#################################", "#################################", "#################################", "#################################", "#################################", "#################################", "#################################", "#################################", "#################################", "################B################", "###############A#A###############", "#################################")
            .aisle("###############A#A###############", "###############A#A###############", "#############BBBBBBB#############", "#################################", "#################################", "#################################", "#################################", "#################################", "#################################", "#################################", "#################################", "#################################", "#################################", "##B###########################B##", "##B###########################B##", "AAB###########################BAA", "##B###########################B##", "AAB###########################BAA", "##B###########################B##", "##B###########################B##", "#################################", "#################################", "#################################", "#################################", "#################################", "#################################", "#################################", "#################################", "#################################", "#################################", "#############BBBBBBB#############", "###############A#A###############", "###############A#A###############")
            .aisle("###############A#A###############", "##############BBBBB##############", "############BB#####BB############", "#################################", "#################################", "#######E#################E#######", "#################################", "#####E#####################E#####", "#################################", "#################################", "#################################", "#################################", "##B###########################B##", "##B###########################B##", "#B#############################B#", "AB#############################BA", "#B#############################B#", "AB#############################BA", "#B#############################B#", "##B###########################B##", "##B###########################B##", "#################################", "#################################", "#################################", "#################################", "#####E#####################E#####", "#################################", "#######E#################E#######", "#################################", "#################################", "############BB#####BB############", "##############BBBBB##############", "###############A#A###############")
            .aisle("###############A#A###############", "#############BBABABB#############", "############B##CCC##B############", "#################################", "######A###################A######", "#######C#################C#######", "####A#######################A####", "#####C#####################C#####", "#################################", "#################################", "#################################", "#################################", "##B###########################B##", "#B#############################B#", "#B#############################B#", "AAC###########################CAA", "#BC###########################CB#", "AAC###########################CAA", "#B#############################B#", "#B#############################B#", "##B###########################B##", "#################################", "#################################", "#################################", "#################################", "#####C#####################C#####", "####A#######################A####", "#######C#################C#######", "######A###################A######", "#################################", "############B##CCC##B############", "#############BBABABB#############", "###############A#A###############")
            .aisle("############AAAAAAAAA############", "#########AAAABAABAABAAAA#########", "#######AAA##B#CDDDC#B##AAA#######", "######AA#################AA######", "#####AA###################AA#####", "####AA#C#################C#AA####", "###AA#######################AA###", "##AA#C#####################C#AA##", "##A###########################A##", "#AA###########################AA#", "#A#############################A#", "#A#############################A#", "AAB###########################BAA", "AB#############################BA", "AAC###########################CAA", "AAD###########################DAA", "ABD###########################DBA", "AAD###########################DAA", "AAC###########################CAA", "AB#############################BA", "AAB###########################BAA", "#A#############################A#", "#A#############################A#", "#AA###########################AA#", "##A###########################A##", "##AA#C#####################C#AA##", "###AA#######################AA###", "####AA#C#################C#AA####", "#####AA###################AA#####", "######AA#################AA######", "#######AAA##B#CDDDC#B##AAA#######", "#########AAAABAABAABAAAA#########", "############AAAAAAAAA############")
            .aisle("###############A#A###############", "#############BBBBBBB#############", "##########BBB#CDDDC#BBB##########", "########BB#############BB########", "######ABDD#############DDBA######", "######BD#################DB######", "####ABD###################DBA####", "####BD#####################DB####", "###BD#######################DB###", "###BD#######################DB###", "##B###########################B##", "##B###########################B##", "##B###########################B##", "#B#############################B#", "#BC###########################CB#", "ABD###########################DBA", "#BD###########################DB#", "ABD###########################DBA", "#BC###########################CB#", "#B#############################B#", "##B###########################B##", "##B###########################B##", "##B###########################B##", "###BD#######################DB###", "###BD#######################DB###", "####BD#####################DB####", "####ABD###################DBA####", "######BD#################DB######", "######ABDD#############DDBA######", "########BB#############BB########", "##########BBB#CDDDC#BBB##########", "#############BBBBBBB#############", "###############A#A###############")
            .aisle("############AAAAAAAAA############", "#########AAAABAABAABAAAA#########", "#######AAA##B#CDDDC#B##AAA#######", "######AA#################AA######", "#####AA###################AA#####", "####AA#C#################C#AA####", "###AA#######################AA###", "##AA#C#####################C#AA##", "##A###########################A##", "#AA###########################AA#", "#A#############################A#", "#A#############################A#", "AAB###########################BAA", "AB#############################BA", "AAC###########################CAA", "AAD###########################DAA", "ABD###########################DBA", "AAD###########################DAA", "AAC###########################CAA", "AB#############################BA", "AAB###########################BAA", "#A#############################A#", "#A#############################A#", "#AA###########################AA#", "##A###########################A##", "##AA#C#####################C#AA##", "###AA#######################AA###", "####AA#C#################C#AA####", "#####AA###################AA#####", "######AA#################AA######", "#######AAA##B#CDDDC#B##AAA#######", "#########AAAABAABAABAAAA#########", "############AAAAAAAAA############")
            .aisle("###############A#A###############", "#############BBABABB#############", "############B##CCC##B############", "#################################", "######A###################A######", "#######C#################C#######", "####A#######################A####", "#####C#####################C#####", "#################################", "#################################", "#################################", "#################################", "##B###########################B##", "#B#############################B#", "#B#############################B#", "AAC###########################CAA", "#BC###########################CB#", "AAC###########################CAA", "#B#############################B#", "#B#############################B#", "##B###########################B##", "#################################", "#################################", "#################################", "#################################", "#####C#####################C#####", "####A#######################A####", "#######C#################C#######", "######A###################A######", "#################################", "############B##CCC##B############", "#############BBABABB#############", "###############A#A###############")
            .aisle("###############A#A###############", "##############BBBBB##############", "############BB#####BB############", "#################################", "#################################", "#######E#################E#######", "#################################", "#####E#####################E#####", "#################################", "#################################", "#################################", "#################################", "##B###########################B##", "##B###########################B##", "#B#############################B#", "AB#############################BA", "#B#############################B#", "AB#############################BA", "#B#############################B#", "##B###########################B##", "##B###########################B##", "#################################", "#################################", "#################################", "#################################", "#####E#####################E#####", "#################################", "#######E#################E#######", "#################################", "#################################", "############BB#####BB############", "##############BBBBB##############", "###############A#A###############")
            .aisle("###############A#A###############", "###############A#A###############", "#############BBBBBBB#############", "#################################", "#################################", "#################################", "#################################", "#################################", "#################################", "#################################", "#################################", "#################################", "#################################", "##B###########################B##", "##B###########################B##", "AAB###########################BAA", "##B###########################B##", "AAB###########################BAA", "##B###########################B##", "##B###########################B##", "#################################", "#################################", "#################################", "#################################", "#################################", "#################################", "#################################", "#################################", "#################################", "#################################", "#############BBBBBBB#############", "###############A#A###############", "###############A#A###############")
            .aisle("#################################", "###############A#A###############", "################B################", "#################################", "#################################", "#################################", "#################################", "#################################", "#################################", "#################################", "#################################", "#################################", "#################################", "#################################", "#################################", "#A#############################A#", "##B###########################B##", "#A#############################A#", "#################################", "#################################", "#################################", "#################################", "#################################", "#################################", "#################################", "#################################", "#################################", "#################################", "#################################", "#################################", "################B################", "###############A#A###############", "#################################")
            .aisle("#################################", "###############A#A###############", "################B################", "#################################", "#################################", "#################################", "#################################", "#################################", "#################################", "#################################", "#################################", "#################################", "#################################", "#################################", "#################################", "#A#############################A#", "##B###########################B##", "#A#############################A#", "#################################", "#################################", "#################################", "#################################", "#################################", "#################################", "#################################", "#################################", "#################################", "#################################", "#################################", "#################################", "################B################", "###############A#A###############", "#################################")
            .aisle("#################################", "###############A#A###############", "###############A#A###############", "################B################", "################D################", "#################################", "#################################", "#################################", "#################################", "#################################", "#################################", "#################################", "#################################", "#################################", "#################################", "#AA###########################AA#", "###BD#######################DB###", "#AA###########################AA#", "#################################", "#################################", "#################################", "#################################", "#################################", "#################################", "#################################", "#################################", "#################################", "#################################", "################D################", "################B################", "###############A#A###############", "###############A#A###############", "#################################")
            .aisle("#################################", "#################################", "###############A#A###############", "################B################", "################D################", "#################################", "#################################", "#################################", "#################################", "#################################", "#################################", "#################################", "#################################", "#################################", "#################################", "##A###########################A##", "###BD#######################DB###", "##A###########################A##", "#################################", "#################################", "#################################", "#################################", "#################################", "#################################", "#################################", "#################################", "#################################", "#################################", "################D################", "################B################", "###############A#A###############", "#################################", "#################################")
            .aisle("#################################", "#################################", "###############A#A###############", "###############A#A###############", "################B################", "#############ECCDCCE#############", "#################################", "#################################", "#################################", "#################################", "#################################", "#################################", "#################################", "#####E#####################E#####", "#####C#####################C#####", "##AA#C#####################C#AA##", "####BD#####################DB####", "##AA#C#####################C#AA##", "#####C#####################C#####", "#####E#####################E#####", "#################################", "#################################", "#################################", "#################################", "#################################", "#################################", "#################################", "#############ECCDCCE#############", "################B################", "###############A#A###############", "###############A#A###############", "#################################", "#################################")
            .aisle("#################################", "#################################", "#################################", "###############A#A###############", "##############AAAAA##############", "################B################", "################D################", "#################################", "#################################", "#################################", "#################################", "#################################", "#################################", "#################################", "####A#######################A####", "###AA#######################AA###", "####ABD###################DBA####", "###AA#######################AA###", "####A#######################A####", "#################################", "#################################", "#################################", "#################################", "#################################", "#################################", "#################################", "################D################", "################B################", "##############AAAAA##############", "###############A#A###############", "#################################", "#################################", "#################################")
            .aisle("#################################", "#################################", "#################################", "#################################", "###############A#A###############", "###############A#A###############", "################B################", "#############ECCDCCE#############", "#################################", "#################################", "#################################", "#################################", "#################################", "#######E#################E#######", "#######C#################C#######", "####AA#C#################C#AA####", "######BD#################DB######", "####AA#C#################C#AA####", "#######C#################C#######", "#######E#################E#######", "#################################", "#################################", "#################################", "#################################", "#################################", "#############ECCDCCE#############", "################B################", "###############A#A###############", "###############A#A###############", "#################################", "#################################", "#################################", "#################################")
            .aisle("#################################", "#################################", "#################################", "#################################", "#################################", "###############A#A###############", "##############AAAAA##############", "################B################", "################D################", "################D################", "#################################", "#################################", "#################################", "#################################", "######A###################A######", "#####AA###################AA#####", "######ABDD#############DDBA######", "#####AA###################AA#####", "######A###################A######", "#################################", "#################################", "#################################", "#################################", "################D################", "################D################", "################B################", "##############AAAAA##############", "###############A#A###############", "#################################", "#################################", "#################################", "#################################", "#################################")
            .aisle("#################################", "#################################", "#################################", "#################################", "#################################", "#################################", "###############A#A###############", "###############A#A###############", "################B################", "################B################", "#################################", "#################################", "#################################", "#################################", "#################################", "######AA#################AA######", "########BB#############BB########", "######AA#################AA######", "#################################", "#################################", "#################################", "#################################", "#################################", "################B################", "################B################", "###############A#A###############", "###############A#A###############", "#################################", "#################################", "#################################", "#################################", "#################################", "#################################")
            .aisle("#################################", "#################################", "#################################", "#################################", "#################################", "#################################", "#################################", "###############A#A###############", "###############A#A###############", "###############A#A###############", "################B################", "################B################", "#############BBBBBBB#############", "############BB#####BB############", "############B##CCC##B############", "#######AAA##B#CDDDC#B##AAA#######", "##########BBB#CDDDC#BBB##########", "#######AAA##B#CDDDC#B##AAA#######", "############B##CCC##B############", "############BB#####BB############", "#############BBBBBBB#############", "################B################", "################B################", "###############A#A###############", "###############A#A###############", "###############A#A###############", "#################################", "#################################", "#################################", "#################################", "#################################", "#################################", "#################################")
            .aisle("#################################", "#################################", "#################################", "#################################", "#################################", "#################################", "#################################", "#################################", "#################################", "###############A#A###############", "###############A#A###############", "###############A#A###############", "###############A#A###############", "##############BBBBB##############", "#############BBABABB#############", "#########AAAABAABAABAAAA#########", "#############BBBBBBB#############", "#########AAAABAABAABAAAA#########", "#############BBABABB#############", "##############BBBBB##############", "###############A#A###############", "###############A#A###############", "###############A#A###############", "###############A#A###############", "#################################", "#################################", "#################################", "#################################", "#################################", "#################################", "#################################", "#################################", "#################################")
            .aisle("#################################", "#################################", "#################################", "#################################", "#################################", "#################################", "#################################", "#################################", "#################################", "#################################", "#################################", "#################################", "#############AAAAAAA#############", "############AAFFFFFAA############", "############AFFFFFFFA############", "############AFFAAAFFA############", "############AFFA@AFFA############", "############AFFAAAFFA############", "############AFFFFFFFA############", "############AAFFFFFAA############", "#############AAAAAAA#############", "#################################", "#################################", "#################################", "#################################", "#################################", "#################################", "#################################", "#################################", "#################################", "#################################", "#################################", "#################################")
            .where("A", Predicates.blocks("minecraft:bricks"))
            .where("#", Predicates.any())
            .where("B", Predicates.blocks("minecraft:oak_planks"))
            .where("C", Predicates.blocks("minecraft:lapis_block"))
            .where("D", Predicates.blocks("minecraft:bookshelf"))
            .where("E", Predicates.blocks("minecraft:chiseled_stone_bricks"))
            .where("F", Predicates.blocks("gtceu:steam_machine_casing")
                .or(Predicates.abilities(PartAbility.STEAM))
                .or(Predicates.abilities(PartAbility.EXPORT_ITEMS))
                .or(Predicates.abilities(PartAbility.STEAM_EXPORT_ITEMS).setPreviewCount(9))
                .or(Predicates.autoAbilities(definition.getRecipeTypes())))
            .where("@", Predicates.controller(Predicates.blocks(definition.get())))
            .build())
        .workableCasingRenderer("gtceu:block/casings/solid/machine_casing_bronze_plated_bricks", 'gtceu:block/multiblock/fusion_reactor')
})

//结构外形来自TST，源结构代码来自GTL